<robot name="right">
	<link name="base_link">
		<inertial>
			<origin xyz="0.00043296 3.5291E-05 0.059942" rpy="0 0 0" />
			<mass value="0.84105" />
			<inertia ixx="0.0017261" ixy="2.5275E-06" ixz="3.6769E-05" iyy="0.0017099" iyz="-1.68E-06" izz="0.00090402" />
		</inertial>
		<visual>
			<origin xyz="0 0 0" rpy="0 0 0" />
			<geometry>
				<mesh filename="realman_meshes/base_link.STL" />
			</geometry>
			<material name="">
				<color rgba="1 1 1 1" />
			</material>
		</visual>
		<collision>
			<origin xyz="0 0 0" rpy="0 0 0" />
			<geometry>
				<mesh filename="realman_meshes/base_link.STL" />
			</geometry>
		</collision>
	</link>
	<link name="Link1">
		<inertial>
			<origin xyz="-2.1376E-07 0.025186 -0.021108" rpy="0 0 0" />
			<mass value="0.59356" />
			<inertia ixx="0.0012661" ixy="-9.8019E-09" ixz="-1.2951E-08" iyy="0.00056135" iyz="-0.00021122" izz="0.0011817" />
		</inertial>
		<visual>
			<origin xyz="0 0 0" rpy="0 0 0" />
			<geometry>
				<mesh filename="realman_meshes/Link1.STL" />
			</geometry>
			<material name="">
				<color rgba="1 1 1 1" />
			</material>
		</visual>
		<collision>
			<origin xyz="0 0 0" rpy="0 0 0" />
			<geometry>
				<mesh filename="realman_meshes/Link1.STL" />
			</geometry>
		</collision>
	</link>
	<joint name="joint1" type="revolute">
		<origin xyz="0 0 0.2405" rpy="-1.5708 0 0" />
		<parent link="base_link" />
		<child link="Link1" />
		<axis xyz="0 -1 0" />
		<limit lower="-3.107" upper="3.107" effort="100.0" velocity="1.00" />
	</joint>
	<link name="Link2">
		<inertial>
			<origin xyz="4.1111E-07 0.011078 0.076129" rpy="0 0 0" />
			<mass value="0.43285" />
			<inertia ixx="0.0012584" ixy="5.6315E-09" ixz="1.3348E-09" iyy="0.0012225" iyz="0.000279" izz="0.00031747" />
		</inertial>
		<visual>
			<origin xyz="0 0 0" rpy="0 0 0" />
			<geometry>
				<mesh filename="realman_meshes/Link2.STL" />
			</geometry>
			<material name="">
				<color rgba="1 1 1 1" />
			</material>
		</visual>
		<collision>
			<origin xyz="0 0 0" rpy="0 0 0" />
			<geometry>
				<mesh filename="realman_meshes/Link2.STL" />
			</geometry>
		</collision>
	</link>
	<joint name="joint2" type="revolute">
		<origin xyz="0 0 0" rpy="1.5708 0 0" />
		<parent link="Link1" />
		<child link="Link2" />
		<axis xyz="0 1 0" />
		<limit lower="-2.269" upper="2.269" effort="100.0" velocity="1.00" />
	</joint>
	<link name="Link3">
		<inertial>
			<origin xyz="-4.7932E-07 0.027347 -0.023544" rpy="0 0 0" />
			<mass value="0.43132" />
			<inertia ixx="0.00079433" ixy="1.0334E-08" ixz="-2.329E-09" iyy="0.00031507" iyz="-0.00014262" izz="0.00073037" />
		</inertial>
		<visual>
			<origin xyz="0 0 0" rpy="0 0 0" />
			<geometry>
				<mesh filename="realman_meshes/Link3.STL" />
			</geometry>
			<material name="">
				<color rgba="1 1 1 1" />
			</material>
		</visual>
		<collision>
			<origin xyz="0 0 0" rpy="0 0 0" />
			<geometry>
				<mesh filename="realman_meshes/Link3.STL" />
			</geometry>
		</collision>
	</link>
	<joint name="joint3" type="revolute">
		<origin xyz="0 0 0.256" rpy="-1.5708 0 0" />
		<parent link="Link2" />
		<child link="Link3" />
		<axis xyz="0 -1 0" />
		<limit lower="-3.107" upper="3.107" effort="100.0" velocity="1.00" />
	</joint>
	<link name="Link4">
		<inertial>
			<origin xyz="5.0444E-06 0.010569 0.059593" rpy="0 0 0" />
			<mass value="0.28963" />
			<inertia ixx="0.00063737" ixy="-3.8666E-08" ixz="7.0522E-08" iyy="0.00061418" iyz="0.00014461" izz="0.00015648" />
		</inertial>
		<visual>
			<origin xyz="0 0 0" rpy="0 0 0" />
			<geometry>
				<mesh filename="realman_meshes/Link4.STL" />
			</geometry>
			<material name="">
				<color rgba="1 1 1 1" />
			</material>
		</visual>
		<collision>
			<origin xyz="0 0 0" rpy="0 0 0" />
			<geometry>
				<mesh filename="realman_meshes/Link4.STL" />
			</geometry>
		</collision>
	</link>
	<joint name="joint4" type="revolute">
		<origin xyz="0 0 0" rpy="1.5708 0 0" />
		<parent link="Link3" />
		<child link="Link4" />
		<axis xyz="0 1 0" />
		<limit lower="-2.356" upper="2.356" effort="100.0" velocity="1.00" />
	</joint>
	<link name="Link5">
		<inertial>
			<origin xyz="1.1466E-06 0.021541 -0.018041" rpy="0 0 0" />
			<mass value="0.23941" />
			<inertia ixx="0.00028594" ixy="1.8435E-09" ixz="2.6611E-09" iyy="0.00011989" iyz="-4.4238E-05" izz="0.00026273" />
		</inertial>
		<visual>
			<origin xyz="0 0 0" rpy="0 0 0" />
			<geometry>
				<mesh filename="realman_meshes/Link5.STL" />
			</geometry>
			<material name="">
				<color rgba="1 1 1 1" />
			</material>
		</visual>
		<collision>
			<origin xyz="0 0 0" rpy="0 0 0" />
			<geometry>
				<mesh filename="realman_meshes/Link5.STL" />
			</geometry>
		</collision>
	</link>
	<joint name="joint5" type="revolute">
		<origin xyz="0 0 0.21" rpy="-1.5708 0 0" />
		<parent link="Link4" />
		<child link="Link5" />
		<axis xyz="0 -1 0" />
		<limit lower="-3.107" upper="3.107" effort="100.0" velocity="1.00" />
	</joint>
	<link name="Link6">
		<inertial>
			<origin xyz="4.5754E-06 0.0073681 0.059382" rpy="0 0 0" />
			<mass value="0.21879" />
			<inertia ixx="0.00035053" ixy="-1.7437E-08" ixz="3.1653E-08" iyy="0.00033447" iyz="7.824E-05" izz="0.00010492" />
		</inertial>
		<visual>
			<origin xyz="0 0 0" rpy="0 0 0" />
			<geometry>
				<mesh filename="realman_meshes/Link6.STL" />
			</geometry>
			<material name="">
				<color rgba="1 1 1 1" />
			</material>
		</visual>
		<collision>
			<origin xyz="0 0 0" rpy="0 0 0" />
			<geometry>
				<mesh filename="realman_meshes/Link6.STL" />
			</geometry>
		</collision>
	</link>
	<joint name="joint6" type="revolute">
		<origin xyz="0 0 0" rpy="1.5708 0 0" />
		<parent link="Link5" />
		<child link="Link6" />
		<axis xyz="0 1 0" />
		<limit lower="-2.234" upper="2.234" effort="100.0" velocity="1.00" />
	</joint>
	<link name="Link7">
		<inertial>
			<origin xyz="0.00032231 -0.0001782 -0.028676" rpy="0 0 0" />
			<mass value="0.14433" />
			<inertia ixx="3.6119E-05" ixy="-1.3242E-06" ixz="-3.2733E-08" iyy="3.4626E-05" iyz="7.6694E-09" izz="6.1463E-05" />
		</inertial>
		<visual>
			<origin xyz="0 0 0" rpy="0 0 0" />
			<geometry>
				<mesh filename="realman_meshes/Link7.STL" />
			</geometry>
			<material name="">
				<color rgba="1 1 1 1" />
			</material>
		</visual>
		<collision>
			<origin xyz="0 0 0" rpy="0 0 0" />
			<geometry>
				<mesh filename="realman_meshes/Link7.STL" />
			</geometry>
		</collision>
	</link>
	<joint name="joint7" type="revolute">
		<origin xyz="0 0 0.1725" rpy="0 0 0" />
		<parent link="Link6" />
		<child link="Link7" />
		<axis xyz="0 0 1" />
		<limit lower="-6.283" upper="6.283" effort="100.0" velocity="1.00" />
	</joint>
	<joint name="joint_eef" type="fixed">
		<origin xyz="0 0 0" rpy="-1.57079 0 3.14159"/>
		<parent link="Link7"/>
		<child link="R_hand_base_link"/>
	</joint>
	<link name="R_hand_base_link">
		<inertial>
			<origin xyz="-0.0025264 -0.066047 0.0019598" rpy="0 0 0" />
			<mass value="0.14143" />
			<inertia ixx="0.00012281" ixy="2.1711E-06" ixz="1.7709E-06" iyy="8.3832E-05" iyz="-1.6551E-06" izz="7.6663E-05" />
		</inertial>
		<visual>
			<origin xyz="0 0 0" rpy="0 0 0" />
			<geometry>
				<mesh filename="inspire_meshes/base_link.STL" />
			</geometry>
			<material name="">
				<color rgba="1 1 1 1" />
			</material>
		</visual>
		<collision>
			<origin xyz="0 0 0" rpy="0 0 0" />
			<geometry>
				<mesh filename="inspire_meshes/base_link.STL" />
			</geometry>
		</collision>
	</link>
	<link name="R_thumb_proximal_base">
		<inertial>
			<origin xyz="-0.0048064 0.0009382 -0.00757" rpy="0 0 0" />
			<mass value="0.0018869" />
			<inertia ixx="5.816E-08" ixy="1.4539E-08" ixz="4.491E-09" iyy="7.9161E-08" iyz="-1.8727E-09" izz="6.7433E-08" />
		</inertial>
		<visual>
			<origin xyz="0 0 0" rpy="0 0 0" />
			<geometry>
				<mesh filename="inspire_meshes/Link11.STL" />
			</geometry>
			<material name="">
				<color rgba="1 1 1 1" />
			</material>
		</visual>
		<collision>
			<origin xyz="0 0 0" rpy="0 0 0" />
			<geometry>
				<mesh filename="inspire_meshes/Link11.STL" />
			</geometry>
		</collision>
	</link>
	<joint name="R_thumb_proximal_yaw_joint" type="revolute">
		<origin xyz="-0.01696 -0.0691 -0.02045" rpy="1.5708 -1.5708 0" />
		<parent link="R_hand_base_link" />
		<child link="R_thumb_proximal_base" />
		<axis xyz="0 0 -1" />
		<limit lower="-0.1" upper="1.3" effort="1.0" velocity="0.5" />
	</joint>
	<link name="R_thumb_proximal">
		<inertial>
			<origin xyz="0.021932 0.012785 -0.0080386" rpy="0 0 0" />
			<mass value="0.0066075" />
			<inertia ixx="1.5686E-06" ixy="-7.8296E-07" ixz="8.9143E-10" iyy="1.7353E-06" iyz="-1.0191E-09" izz="2.786E-06" />
		</inertial>
		<visual>
			<origin xyz="0 0 0" rpy="0 0 0" />
			<geometry>
				<mesh filename="inspire_meshes/Link12.STL" />
			</geometry>
			<material name="">
				<color rgba="1 1 1 1" />
			</material>
		</visual>
		<collision>
			<origin xyz="0 0 0" rpy="0 0 0" />
			<geometry>
				<mesh filename="inspire_meshes/Link12.STL" />
			</geometry>
		</collision>
	</link>
	<joint name="R_thumb_proximal_pitch_joint" type="revolute">
		<origin xyz="-0.0088099 0.010892 -0.00925" rpy="1.5708 0 2.8587" />
		<parent link="R_thumb_proximal_base" />
		<child link="R_thumb_proximal" />
		<axis xyz="0 0 1" />
		<limit lower="-0.1" upper="0.6" effort="1.0" velocity="0.5" />
	</joint>
	<link name="R_thumb_intermediate">
		<inertial>
			<origin xyz="0.0095544 -0.0016282 -0.0071997" rpy="0 0 0" />
			<mass value="0.0037847" />
			<inertia ixx="3.6981E-07" ixy="-9.8581E-08" ixz="-4.7469E-12" iyy="3.2394E-07" iyz="1.0939E-12" izz="4.6531E-07" />
		</inertial>
		<visual>
			<origin xyz="0 0 0" rpy="0 0 0" />
			<geometry>
				<mesh filename="inspire_meshes/Link13.STL" />
			</geometry>
			<material name="">
				<color rgba="1 1 1 1" />
			</material>
		</visual>
		<collision>
			<origin xyz="0 0 0" rpy="0 0 0" />
			<geometry>
				<mesh filename="inspire_meshes/Link13.STL" />
			</geometry>
		</collision>
	</link>
	<joint name="R_thumb_intermediate_joint" type="revolute">
		<origin xyz="0.04407 0.034553 -0.0008" rpy="0 0 0" />
		<parent link="R_thumb_proximal" />
		<child link="R_thumb_intermediate" />
		<axis xyz="0 0 1" />
		<limit lower="0" upper="0.8" effort="1.0" velocity="0.5" />
		<mimic joint="R_thumb_proximal_pitch_joint" multiplier="1.6" offset="0" />
	</joint>
	<link name="R_thumb_distal">
		<inertial>
			<origin xyz="0.0092888 0.0049529 -0.0060033" rpy="0 0 0" />
			<mass value="0.0033441" />
			<inertia ixx="1.3632E-07" ixy="-5.6788E-08" ixz="-9.2764E-11" iyy="1.4052E-07" iyz="-1.2283E-10" izz="2.0026E-07" />
		</inertial>
		<visual>
			<origin xyz="0 0 0" rpy="0 0 0" />
			<geometry>
				<mesh filename="inspire_meshes/Link14.STL" />
			</geometry>
			<material name="">
				<color rgba="1 1 1 1" />
			</material>
		</visual>
		<collision>
			<origin xyz="0 0 0" rpy="0 0 0" />
			<geometry>
				<mesh filename="inspire_meshes/Link14.STL" />
			</geometry>
		</collision>
	</link>
	<joint name="R_thumb_distal_joint" type="revolute">
		<origin xyz="0.020248 0.010156 -0.0012" rpy="0 0 0" />
		<parent link="R_thumb_intermediate" />
		<child link="R_thumb_distal" />
		<axis xyz="0 0 1" />
		<limit lower="0" upper="1.2" effort="1.0" velocity="0.5" />
		<mimic joint="R_thumb_proximal_pitch_joint" multiplier="2.4" offset="0" />
	</joint>
	<link name="R_thumb_tip">
		<!-- <visual>
			<geometry>
				<cylinder length="0.001" radius="0.0005"/>
			</geometry>
    	</visual> -->
	</link>
	<joint name="R_thumb_tip_joint" type="fixed">
		<origin xyz="0.012 0.015 -0.005" rpy="0 0 0" />
		<parent link="R_thumb_distal" />
		<child link="R_thumb_tip" />
	</joint>
	<link name="R_index_proximal">
		<inertial>
			<origin xyz="0.0012259 0.011942 -0.0060001" rpy="0 0 0" />
			<mass value="0.0042403" />
			<inertia ixx="6.6232E-07" ixy="-1.5775E-08" ixz="1.8515E-12" iyy="2.1146E-07" iyz="-5.0828E-12" izz="6.9398E-07" />
		</inertial>
		<visual>
			<origin xyz="0 0 0" rpy="0 0 0" />
			<geometry>
				<mesh filename="inspire_meshes/Link15.STL" />
			</geometry>
			<material name="">
				<color rgba="1 1 1 1" />
			</material>
		</visual>
		<collision>
			<origin xyz="0 0 0" rpy="0 0 0" />
			<geometry>
				<mesh filename="inspire_meshes/Link15.STL" />
			</geometry>
		</collision>
	</link>
	<joint name="R_index_proximal_joint" type="revolute">
		<origin xyz="0.00028533 -0.13653 -0.032268" rpy="-3.1067 0 0" />
		<parent link="R_hand_base_link" />
		<child link="R_index_proximal" />
		<axis xyz="0 0 1" />
		<limit lower="0" upper="1.7" effort="1.0" velocity="0.5" />
	</joint>
	<link name="R_index_intermediate">
		<inertial>
			<origin xyz="0.0019697 0.019589 -0.005" rpy="0 0 0" />
			<mass value="0.0045683" />
			<inertia ixx="7.6111E-07" ixy="8.7637E-08" ixz="-3.7751E-13" iyy="9.6076E-08" iyz="9.9444E-13" izz="7.8179E-07" />
		</inertial>
		<visual>
			<origin xyz="0 0 0" rpy="0 0 0" />
			<geometry>
				<mesh filename="inspire_meshes/Link16.STL" />
			</geometry>
			<material name="">
				<color rgba="1 1 1 1" />
			</material>
		</visual>
		<collision>
			<origin xyz="0 0 0" rpy="0 0 0" />
			<geometry>
				<mesh filename="inspire_meshes/Link16.STL" />
			</geometry>
		</collision>
	</link>
	<joint name="R_index_intermediate_joint" type="revolute">
		<origin xyz="-0.0026138 0.032026 -0.001" rpy="0 0 0" />
		<parent link="R_index_proximal" />
		<child link="R_index_intermediate" />
		<axis xyz="0 0 1" />
		<limit lower="0" upper="1.7" effort="1.0" velocity="0.5" />
		<mimic joint="R_index_proximal_joint" multiplier="1" offset="0" />
	</joint>
	<link name="R_index_tip">
		<!-- <visual>
			<geometry>
				<cylinder length="0.001" radius="0.0005"/>
			</geometry>
    	</visual> -->
	</link>
	<joint name="R_index_tip_joint" type="fixed">
		<origin xyz="-0.0057 0.040 -0.005" rpy="0 0 0" />
		<parent link="R_index_intermediate" />
		<child link="R_index_tip" />
	</joint>
	<link name="R_middle_proximal">
		<inertial>
			<origin xyz="0.001297 0.011934 -0.0060001" rpy="0 0 0" />
			<mass value="0.0042403" />
			<inertia ixx="6.6211E-07" ixy="-1.8461E-08" ixz="1.8002E-12" iyy="2.1167E-07" iyz="-6.6808E-12" izz="6.9397E-07" />
		</inertial>
		<visual>
			<origin xyz="0 0 0" rpy="0 0 0" />
			<geometry>
				<mesh filename="inspire_meshes/Link17.STL" />
			</geometry>
			<material name="">
				<color rgba="1 1 1 1" />
			</material>
		</visual>
		<collision>
			<origin xyz="0 0 0" rpy="0 0 0" />
			<geometry>
				<mesh filename="inspire_meshes/Link17.STL" />
			</geometry>
		</collision>
	</link>
	<joint name="R_middle_proximal_joint" type="revolute">
		<origin xyz="0.00028533 -0.1371 -0.01295" rpy="-3.1416 0 0" />
		<parent link="R_hand_base_link" />
		<child link="R_middle_proximal" />
		<axis xyz="0 0 1" />
		<limit lower="0" upper="1.7" effort="1.0" velocity="0.5" />
	</joint>
	<link name="R_middle_intermediate">
		<inertial>
			<origin xyz="0.001921 0.020796 -0.005" rpy="0 0 0" />
			<mass value="0.0050396" />
			<inertia ixx="9.5822E-07" ixy="1.1425E-07" ixz="-2.4791E-12" iyy="1.0646E-07" iyz="5.9173E-12" izz="9.8384E-07" />
		</inertial>
		<visual>
			<origin xyz="0 0 0" rpy="0 0 0" />
			<geometry>
				<mesh filename="inspire_meshes/Link18.STL" />
			</geometry>
			<material name="">
				<color rgba="1 1 1 1" />
			</material>
		</visual>
		<collision>
			<origin xyz="0 0 0" rpy="0 0 0" />
			<geometry>
				<mesh filename="inspire_meshes/Link18.STL" />
			</geometry>
		</collision>
	</link>
	<joint name="R_middle_intermediate_joint" type="revolute">
		<origin xyz="-0.0024229 0.032041 -0.001" rpy="0 0 0" />
		<parent link="R_middle_proximal" />
		<child link="R_middle_intermediate" />
		<axis xyz="0 0 1" />
		<limit lower="0" upper="1.7" effort="1.0" velocity="0.5" />
		<mimic joint="R_middle_proximal_joint" multiplier="1" offset="0" />
	</joint>
	<link name="R_middle_tip">
		<!-- <visual>
			<geometry>
				<cylinder length="0.001" radius="0.0005"/>
			</geometry>
    	</visual> -->
	</link>
	<joint name="R_middle_tip_joint" type="fixed">
		<origin xyz="-0.0057 0.044 -0.005" rpy="0 0 0" />
		<parent link="R_middle_intermediate" />
		<child link="R_middle_tip" />
	</joint>
	<link name="R_ring_proximal">
		<inertial>
			<origin xyz="0.001297 0.011934 -0.0060002" rpy="0 0 0" />
			<mass value="0.0042403" />
			<inertia ixx="6.6211E-07" ixy="-1.8461E-08" ixz="1.5793E-12" iyy="2.1167E-07" iyz="-6.6868E-12" izz="6.9397E-07" />
		</inertial>
		<visual>
			<origin xyz="0 0 0" rpy="0 0 0" />
			<geometry>
				<mesh filename="inspire_meshes/Link19.STL" />
			</geometry>
			<material name="">
				<color rgba="1 1 1 1" />
			</material>
		</visual>
		<collision>
			<origin xyz="0 0 0" rpy="0 0 0" />
			<geometry>
				<mesh filename="inspire_meshes/Link19.STL" />
			</geometry>
		</collision>
	</link>
	<joint name="R_ring_proximal_joint" type="revolute">
		<origin xyz="0.00028533 -0.13691 0.0062872" rpy="3.0892 0 0" />
		<parent link="R_hand_base_link" />
		<child link="R_ring_proximal" />
		<axis xyz="0 0 1" />
		<limit lower="0" upper="1.7" effort="1.0" velocity="0.5" />
	</joint>
	<link name="R_ring_intermediate">
		<inertial>
			<origin xyz="0.0021753 0.019567 -0.005" rpy="0 0 0" />
			<mass value="0.0045683" />
			<inertia ixx="7.6286E-07" ixy="8.0635E-08" ixz="-6.1562E-13" iyy="9.431E-08" iyz="5.8619E-13" izz="7.8177E-07" />
		</inertial>
		<visual>
			<origin xyz="0 0 0" rpy="0 0 0" />
			<geometry>
				<mesh filename="inspire_meshes/Link20.STL" />
			</geometry>
			<material name="">
				<color rgba="1 1 1 1" />
			</material>
		</visual>
		<collision>
			<origin xyz="0 0 0" rpy="0 0 0" />
			<geometry>
				<mesh filename="inspire_meshes/Link20.STL" />
			</geometry>
		</collision>
	</link>
	<joint name="R_ring_intermediate_joint" type="revolute">
		<origin xyz="-0.0024229 0.032041 -0.001" rpy="0 0 0" />
		<parent link="R_ring_proximal" />
		<child link="R_ring_intermediate" />
		<axis xyz="0 0 1" />
		<limit lower="0" upper="1.7" effort="1.0" velocity="0.5" />
		<mimic joint="R_ring_proximal_joint" multiplier="1" offset="0" />
	</joint>
	<link name="R_ring_tip">
		<!-- <visual>
			<geometry>
				<cylinder length="0.001" radius="0.0005"/>
			</geometry>
    	</visual> -->
	</link>
	<joint name="R_ring_tip_joint" type="fixed">
		<origin xyz="-0.005 0.041 -0.005" rpy="0 0 0" />
		<parent link="R_ring_intermediate" />
		<child link="R_ring_tip" />
	</joint>
	<link name="R_pinky_proximal">
		<inertial>
			<origin xyz="0.001297 0.011934 -0.0060001" rpy="0 0 0" />
			<mass value="0.0042403" />
			<inertia ixx="6.6211E-07" ixy="-1.8461E-08" ixz="1.6907E-12" iyy="2.1167E-07" iyz="-6.9334E-12" izz="6.9397E-07" />
		</inertial>
		<visual>
			<origin xyz="0 0 0" rpy="0 0 0" />
			<geometry>
				<mesh filename="inspire_meshes/Link21.STL" />
			</geometry>
			<material name="">
				<color rgba="1 1 1 1" />
			</material>
		</visual>
		<collision>
			<origin xyz="0 0 0" rpy="0 0 0" />
			<geometry>
				<mesh filename="inspire_meshes/Link21.STL" />
			</geometry>
		</collision>
	</link>
	<joint name="R_pinky_proximal_joint" type="revolute">
		<origin xyz="0.00028533 -0.13571 0.025488" rpy="3.0369 0 0" />
		<parent link="R_hand_base_link" />
		<child link="R_pinky_proximal" />
		<axis xyz="0 0 1" />
		<limit lower="0" upper="1.7" effort="1.0" velocity="0.5" />
	</joint>
	<link name="R_pinky_intermediate">
		<inertial>
			<origin xyz="0.0024748 0.016203 -0.0050031" rpy="0 0 0" />
			<mass value="0.0035996" />
			<inertia ixx="4.3913E-07" ixy="4.1418E-08" ixz="3.7168E-11" iyy="7.0247E-08" iyz="5.8613E-11" izz="4.4867E-07" />
		</inertial>
		<visual>
			<origin xyz="0 0 0" rpy="0 0 0" />
			<geometry>
				<mesh filename="inspire_meshes/Link22.STL" />
			</geometry>
			<material name="">
				<color rgba="1 1 1 1" />
			</material>
		</visual>
		<collision>
			<origin xyz="0 0 0" rpy="0 0 0" />
			<geometry>
				<mesh filename="inspire_meshes/Link22.STL" />
			</geometry>
		</collision>
	</link>
	<joint name="R_pinky_intermediate_joint" type="revolute">
		<origin xyz="-0.0024229 0.032041 -0.001" rpy="0 0 0" />
		<parent link="R_pinky_proximal" />
		<child link="R_pinky_intermediate" />
		<axis xyz="0 0 1" />
		<limit lower="0" upper="1.7" effort="1.0" velocity="0.5" />
		<mimic joint="R_pinky_proximal_joint" multiplier="1" offset="0" />
	</joint>
	<link name="R_pinky_tip">
		<!-- <visual>
			<geometry>
				<cylinder length="0.001" radius="0.0005"/>
			</geometry>
    	</visual> -->
	</link>
	<joint name="R_pinky_tip_joint" type="fixed">
		<origin xyz="-0.0045 0.033 -0.005" rpy="0 0 0" />
		<parent link="R_pinky_intermediate" />
		<child link="R_pinky_tip" />
	</joint>
</robot>
